<?xml version="1.0" ?>
<sdf version="1.8">
    <world name="single_robot_clean">
        <physics name="1ms" type="ignored">
            <max_step_size>0.001</max_step_size>
            <real_time_factor>1.0</real_time_factor>
        </physics>
        <plugin filename="gz-sim-physics-system" name="gz::sim::systems::Physics"></plugin>
        <plugin filename="gz-sim-user-commands-system" name="gz::sim::systems::UserCommands"></plugin>
        <plugin filename="gz-sim-scene-broadcaster-system" name="gz::sim::systems::SceneBroadcaster"></plugin>
        <plugin filename="gz-sim-sensors-system" name="gz::sim::systems::Sensors">
            <render_engine>ogre2</render_engine>
        </plugin>
        
        <gui fullscreen="0">
            <plugin filename="MinimalScene" name="3D View">
                <gz-gui>
                    <title>3D View</title>
                    <property type="bool" key="showTitleBar">false</property>
                    <property type="string" key="state">docked</property>
                </gz-gui>
                <engine>ogre2</engine>
                <scene>scene</scene>
                <ambient_light>0.4 0.4 0.4</ambient_light>
                <background_color>0.8 0.8 0.8</background_color>
                <camera_pose>-6 0 6 0 0.5 0</camera_pose>
            </plugin>
            <plugin filename="GzSceneManager" name="Scene Manager"></plugin>
            <plugin filename="WorldControl" name="World control"></plugin>
            <plugin filename="WorldStats" name="World stats"></plugin>
            <plugin filename="KeyPublisher" name="Key Publisher"/>
        </gui>

        <light type="directional" name="sun">
            <cast_shadows>true</cast_shadows>
            <pose>0 0 10 0 0 0</pose>
            <diffuse>0.8 0.8 0.8 1</diffuse>
            <specular>0.2 0.2 0.2 1</specular>
            <direction>-0.5 0.1 -0.9</direction>
        </light>

        <model name="ground_plane">
            <static>true</static>
            <link name="link">
                <collision name="collision">
                    <geometry><plane><normal>0 0 1</normal></plane></geometry>
                </collision>
                <visual name="visual">
                    <geometry><plane><normal>0 0 1</normal><size>100 100</size></plane></geometry>
                    <material>
                        <ambient>0.8 0.8 0.8 1</ambient>
                        <diffuse>0.8 0.8 0.8 1</diffuse>
                    </material>
                </visual>
            </link>
        </model>

        <model name='vehicle_blue' canonical_link='chassis'>
            <pose relative_to='world'>0 0 0.325 0 0 0</pose>

            <frame name="lidar_frame" attached_to='chassis'>
                <pose>0.8 0 0.45 0 0 0</pose>
            </frame>

            <link name='chassis'>
                <pose relative_to='__model__'>0.5 0 0.6 0 0 0</pose>
                <inertial>
                    <mass>2.0</mass>
                    <inertia>
                        <ixx>0.126164</ixx><ixy>0</ixy><ixz>0</ixz>
                        <iyy>0.416519</iyy><iyz>0</iyz><izz>0.481014</izz>
                    </inertia>
                </inertial>
                <visual name='visual'>
                    <geometry><box><size>2.5 1.0 0.8</size></box></geometry>
                    <material>
                        <!-- Yellow Chassis (Red 1.0 + Green 1.0) -->
                        <ambient>1.0 1.0 0.0 1</ambient>
                        <diffuse>1.0 1.0 0.0 1</diffuse>
                        <specular>1.0 1.0 0.0 1</specular>
                    </material>
                </visual>
                <collision name='collision'>
                    <geometry><box><size>2.5 1.0 0.8</size></box></geometry>
                </collision>
                
                <sensor name="imu_sensor" type="imu">
                    <always_on>1</always_on>
                    <update_rate>1</update_rate>
                    <visualize>true</visualize>
                    <topic>imu</topic>
                </sensor>
                <sensor name='gpu_lidar' type='gpu_lidar'>
                    <pose relative_to='lidar_frame'>0 0 0 0 0 0</pose>
                    <topic>lidar</topic>
                    <update_rate>10</update_rate>
                    <ray>
                        <scan>
                            <horizontal>
                                <samples>640</samples><resolution>1</resolution>
                                <min_angle>-1.396263</min_angle><max_angle>1.396263</max_angle>
                            </horizontal>
                            <vertical>
                                <samples>1</samples><resolution>0.01</resolution>
                                <min_angle>0</min_angle><max_angle>0</max_angle>
                            </vertical>
                        </scan>
                        <range><min>0.08</min><max>10.0</max><resolution>0.01</resolution></range>
                    </ray>
                    <always_on>1</always_on>
                    <visualize>true</visualize>
                </sensor>

                <visual name='spoiler_left'>
                    <pose>-1.0 0.4 0.6 0 -0.5 0</pose> 
                    <geometry><box><size>0.1 0.05 0.5</size></box></geometry>
                    <material><ambient>1 0 0 1</ambient><diffuse>1 0 0 1</diffuse></material>
                </visual>

                <visual name='spoiler_right'>
                    <pose>-1.0 -0.4 0.6 0 -0.5 0</pose> 
                    <geometry><box><size>0.1 0.05 0.5</size></box></geometry>
                    <material><ambient>1 0 0 1</ambient><diffuse>1 0 0 1</diffuse></material>
                </visual>

                <visual name='spoiler_wing'>
                    <pose>-1.15 0 0.85 0 0.2 0</pose> 
                    <geometry><box><size>0.4 1.2 0.05</size></box></geometry>
                    <material><ambient>1 0 0 1</ambient><diffuse>1 0 0 1</diffuse></material>
                </visual>

            </link>

            <link name='left_wheel'>
                <pose relative_to="chassis">-0.5 0.6 -0.2 -1.5707 0 0</pose> 
                <inertial>
                    <mass>2</mass>
                    <inertia>
                        <ixx>0.145833</ixx><ixy>0</ixy><ixz>0</ixz>
                        <iyy>0.145833</iyy><iyz>0</iyz><izz>0.125</izz>
                    </inertia>
                </inertial>
                <visual name='visual'>
                    <geometry><cylinder><radius>0.4</radius><length>0.2</length></cylinder></geometry>
                    <material>
                        <!-- Orange Wheels (Red 1.0 + Green 0.5) -->
                        <ambient>1.0 0.5 0.0 1</ambient>
                        <diffuse>1.0 0.5 0.0 1</diffuse>
                    </material>
                </visual>
                <collision name='collision'>
                    <geometry><cylinder><radius>0.4</radius><length>0.2</length></cylinder></geometry>
                </collision>
            </link>

            <link name='right_wheel'>
                <pose relative_to="chassis">-0.5 -0.6 -0.2 -1.5707 0 0</pose>
                <inertial>
                    <mass>1</mass>
                    <inertia>
                        <ixx>0.145833</ixx><ixy>0</ixy><ixz>0</ixz>
                        <iyy>0.145833</iyy><iyz>0</iyz><izz>0.125</izz>
                    </inertia>
                </inertial>
                <visual name='visual'>
                    <geometry><cylinder><radius>0.4</radius><length>0.2</length></cylinder></geometry>
                    <material>
                        <!-- Orange Wheels (Red 1.0 + Green 0.5) -->
                        <ambient>1.0 0.5 0.0 1</ambient>
                        <diffuse>1.0 0.5 0.0 1</diffuse>
                    </material>
                </visual>
                <collision name='collision'>
                    <geometry><cylinder><radius>0.4</radius><length>0.2</length></cylinder></geometry>
                </collision>
            </link>

            <frame name="caster_frame" attached_to='chassis'>
                <pose>0.8 0 -0.4 0 0 0</pose>
            </frame>

            <link name='caster'>
                <pose relative_to='caster_frame'/>
                <inertial>
                    <mass>1</mass>
                    <inertia><ixx>0.1</ixx><ixy>0</ixy><ixz>0</ixz><iyy>0.1</iyy><iyz>0</iyz><izz>0.1</izz></inertia>
                </inertial>
                <visual name='visual'>
                    <geometry><sphere><radius>0.2</radius></sphere></geometry>
                    <material>
                        <!-- Orange Wheels (Red 1.0 + Green 0.5) -->
                        <ambient>1.0 0.5 0.0 1</ambient>
                        <diffuse>1.0 0.5 0.0 1</diffuse>
                    </material>
                </visual>
                <collision name='collision'>
                    <geometry><sphere><radius>0.2</radius></sphere></geometry>
                </collision>
            </link>

            <joint name='left_wheel_joint' type='revolute'>
                <pose relative_to='left_wheel'/>
                <parent>chassis</parent><child>left_wheel</child>
                <axis><xyz expressed_in='__model__'>0 1 0</xyz><limit><lower>-1e16</lower><upper>1e16</upper></limit></axis>
            </joint>

            <joint name='right_wheel_joint' type='revolute'>
                <pose relative_to='right_wheel'/>
                <parent>chassis</parent><child>right_wheel</child>
                <axis><xyz expressed_in='__model__'>0 1 0</xyz><limit><lower>-1e16</lower><upper>1e16</upper></limit></axis>
            </joint>

            <joint name='caster_wheel' type='ball'>
                <parent>chassis</parent><child>caster</child>
            </joint>

            <plugin filename="gz-sim-diff-drive-system" name="gz::sim::systems::DiffDrive">
                <left_joint>left_wheel_joint</left_joint>
                <right_joint>right_wheel_joint</right_joint>
                <wheel_separation>1.2</wheel_separation>
                <wheel_radius>0.4</wheel_radius>
                <odom_publish_frequency>1</odom_publish_frequency>
                <topic>cmd_vel</topic>
            </plugin>
        </model>

        <plugin filename="gz-sim-triggered-publisher-system" name="gz::sim::systems::TriggeredPublisher">
            <input type="gz.msgs.Int32" topic="/keyboard/keypress"><match field="data">16777234</match></input>
            <output type="gz.msgs.Twist" topic="/cmd_vel">linear: {x: 0.0}, angular: {z: 0.5}</output>
        </plugin>
        <plugin filename="gz-sim-triggered-publisher-system" name="gz::sim::systems::TriggeredPublisher">
            <input type="gz.msgs.Int32" topic="/keyboard/keypress"><match field="data">16777235</match></input>
            <output type="gz.msgs.Twist" topic="/cmd_vel">linear: {x: 0.5}, angular: {z: 0.0}</output>
        </plugin>
        <plugin filename="gz-sim-triggered-publisher-system" name="gz::sim::systems::TriggeredPublisher">
            <input type="gz.msgs.Int32" topic="/keyboard/keypress"><match field="data">16777236</match></input>
            <output type="gz.msgs.Twist" topic="/cmd_vel">linear: {x: 0.0}, angular: {z: -0.5}</output>
        </plugin>
        <plugin filename="gz-sim-triggered-publisher-system" name="gz::sim::systems::TriggeredPublisher">
            <input type="gz.msgs.Int32" topic="/keyboard/keypress"><match field="data">16777237</match></input>
            <output type="gz.msgs.Twist" topic="/cmd_vel">linear: {x: -0.5}, angular: {z: 0.0}</output>
        </plugin>
    </world>
</sdf>